<?xml version="1.0" encoding="utf-8"?>
<mujoco model="anymal">
  <compiler angle="radian" meshdir="assets" autolimits="true"/>

  <option cone="elliptic" impratio="100"/>

  <default>
    <default class="anymal">
      <geom friction="0.8" margin="0.001" condim="1"/>
      <joint damping="2" armature="0.01" frictionloss="0.2"/>
      <motor ctrlrange="-80 80" ctrllimited="true"/>

      <default class="haa">
        <joint axis="1 0 0"/>
      </default>

      <default class="hfe">
        <joint axis="1 0 0" range="-9.42477796077 9.42477796077"/>
      </default>

      <default class="kfe">
        <joint axis="1 0 0" range="-9.42477796077 9.42477796077"/>
      </default>

      <default class="foot">
        <site group="1"/>
        <geom rgba="0.2 0.2 0.2 1"/>
      </default>

      <default class="visual">
        <geom type="mesh" contype="0" conaffinity="0" group="2"/>
      </default>

      <default class="collision">
        <geom group="3"/>
        <default class="foot_collision">
          <geom size="0.03" priority="1" solimp="0.015 1 0.031" condim="6" friction="0.8 0.02 0.01"/>
        </default>
      </default>
    </default>
  </default>

  <asset>
    <material name="metal" rgba="0.7 0.7 0.75 1"/>
    <material name="black" rgba="0.1 0.1 0.1 1"/>
    <material name="gray" rgba="0.5 0.5 0.5 1"/>
    <material name="orange" rgba="1 0.5 0 1"/>

    <!-- Mesh files - these should be in the assets directory -->
    <mesh file="base.stl"/>
    <mesh file="top_shell.stl"/>
    <mesh file="bottom_shell.stl"/>
    <mesh file="remote.stl"/>
    <mesh file="handle.stl"/>
    <mesh file="face.stl"/>
    <mesh file="battery.stl"/>
    <mesh file="drive.stl"/>
    <mesh file="hip_l.stl"/>
    <mesh file="hip_r.stl"/>
    <mesh file="thigh.stl"/>
    <mesh file="shank_l.stl"/>
    <mesh file="shank_r.stl"/>
    <mesh file="foot.stl"/>
    <mesh file="depth_camera.stl"/>
    <mesh file="wide_angle_camera.stl"/>
    <mesh file="lidar_cage.stl"/>
    <mesh file="lidar.stl"/>
  </asset>

  <worldbody>
    <body name="base" pos="0 0 0.5" childclass="anymal">
      <!-- Main base inertia -->
      <inertial pos="-0.018 -0.002 0.024" mass="6.222"
                diaginertia="0.372497653 0.370887745 0.017938806"/>

      <freejoint/>

      <!-- Base visual -->
      <geom mesh="base" material="gray" class="visual"/>
      <geom mesh="top_shell" material="gray" class="visual"/>
      <geom mesh="bottom_shell" material="gray" class="visual"/>
      <geom mesh="remote" material="black" class="visual"/>
      <geom mesh="handle" material="metal" class="visual"/>
      <geom mesh="battery" material="black" class="visual"/>

      <!-- Base collision -->
      <geom size="0.29 0.07 0.09" type="box" class="collision"/>
      <geom size="0.09 0.0725" pos="0.2175 0.07 0" quat="0.707107 0.707107 0 0" type="cylinder" class="collision"/>
      <geom size="0.09 0.0725" pos="-0.2175 0.07 0" quat="0.707107 0.707107 0 0" type="cylinder" class="collision"/>
      <geom size="0.09 0.0725" pos="0.2175 -0.07 0" quat="0.707107 0.707107 0 0" type="cylinder" class="collision"/>
      <geom size="0.09 0.0725" pos="-0.2175 -0.07 0" quat="0.707107 0.707107 0 0" type="cylinder" class="collision"/>

      <!-- IMU sensor location -->
      <site name="imu" pos="0.2488 0.00835 0.04628" quat="0.707107 0 0 0.707107"/>

      <!-- Front faces with cameras -->
      <body name="face_front" pos="0.4145 0 0">
        <inertial pos="0.042 -0.001 0.004" mass="0.73"
                  diaginertia="0.005238611 0.004325938 0.002643098"/>
        <geom mesh="face" material="gray" class="visual"/>
        <geom size="0.055 0.07 0.09" type="box" pos="0.055 0 0" class="collision"/>
      </body>

      <body name="face_rear" pos="-0.4145 0 0" quat="0 0 1 0">
        <inertial pos="0.042 -0.001 0.004" mass="0.73"
                  diaginertia="0.005238611 0.004325938 0.002643098"/>
        <geom mesh="face" material="gray" class="visual"/>
        <geom size="0.055 0.07 0.09" type="box" pos="0.055 0 0" class="collision"/>
      </body>

      <!-- LF Leg (Left Front) -->
      <body name="LF_hip_link" pos="0.2999 0.104 0" quat="0.5 0.5 0.5 0.5">
        <inertial pos="-0.063 0.00007 0.00046" mass="2.04"
                  diaginertia="0.001805509 0.001765827 0.001053013"/>
        <geom mesh="drive" material="metal" class="visual"/>

        <joint name="LF_HAA" class="haa" range="-0.72 0.49"/>

        <body name="LF_hip" pos="0 0 0" quat="0.5 -0.5 -0.5 0.5">
          <inertial pos="0.048 0.008 -0.003" mass="0.74"
                    diaginertia="0.003897509 0.003798579 0.001393106"/>
          <geom mesh="hip_l" material="gray" class="visual"/>

          <body name="LF_thigh_link" pos="0.0599 0.08381 0" quat="0.707107 0 0 0.707107">
            <inertial pos="-0.063 0.00007 0.00046" mass="2.04"
                      diaginertia="0.001805509 0.001765827 0.001053013"/>
            <geom mesh="drive" material="metal" class="visual"/>
            <geom size="0.05 0.07" pos="-0.07 0 0" quat="0.707107 0.707107 0 0" type="cylinder" class="collision"/>

            <joint name="LF_HFE" class="hfe"/>

            <body name="LF_thigh" pos="0 0 0" quat="0.707107 0 0 -0.707107">
              <inertial pos="0.0 0.018 -0.169" mass="1.03"
                        diaginertia="0.019312599 0.018644469 0.002838361"/>
              <geom mesh="thigh" material="gray" class="visual"/>
              <geom size="0.065 0.04" pos="0 0.04 0" quat="0.707107 0.707107 0 0" type="cylinder" class="collision"/>
              <geom size="0.0375 0.03 0.1413135" pos="0 0.03 -0.1413135" type="box" class="collision"/>

              <body name="LF_shank_link" pos="0 0.1003 -0.285" quat="0.707107 0 0 0.707107">
                <inertial pos="-0.063 0.00007 0.00046" mass="2.04"
                          diaginertia="0.001805509 0.001765827 0.001053013"/>
                <geom mesh="drive" material="metal" class="visual"/>
                <geom size="0.05 0.07" pos="-0.07 0 0" quat="0.707107 0.707107 0 0" type="cylinder" class="collision"/>

                <joint name="LF_KFE" class="kfe"/>

                <body name="LF_shank" pos="0 0 0" quat="0.707107 0 0 -0.707107">
                  <inertial pos="0.03463 0.00688 0.00098" mass="0.33742"
                            diaginertia="0.00110974122 0.00089388521 0.00032748005"/>
                  <geom mesh="shank_l" material="gray" class="visual"/>
                  <geom size="0.06 0.02" pos="0 0.02 0" quat="0.707107 0.707107 0 0" type="cylinder" class="collision"/>

                  <body name="LF_foot" pos="0.08795 0.01305 -0.33797">
                    <inertial pos="0.00948 -0.00948 0.1468" mass="0.25"
                              diaginertia="0.00317174097 0.00317174092 8.319196e-05"/>
                    <geom mesh="foot" material="black" class="visual" euler="0 0 -0.785398163397"/>
                    <geom size="0.0175 0.141252" type="cylinder" pos="0 0 0.168985" class="collision"/>
                    <geom name="LF_foot" type="sphere" pos="0 0 0.0225" class="foot_collision"/>
                    <site name="LF_foot" class="foot" pos="0 0 0.0225"/>
                  </body>
                </body>
              </body>
            </body>
          </body>
        </body>
      </body>

      <!-- RF Leg (Right Front) -->
      <body name="RF_hip_link" pos="0.2999 -0.104 0" quat="-0.5 0.5 0.5 0.5">
        <inertial pos="-0.063 0.00007 0.00046" mass="2.04"
                  diaginertia="0.001805509 0.001765827 0.001053013"/>
        <geom mesh="drive" material="metal" class="visual"/>

        <joint name="RF_HAA" class="haa" range="-0.49 0.72"/>

        <body name="RF_hip" pos="0 0 0" quat="-0.5 -0.5 -0.5 0.5">
          <inertial pos="0.048 -0.008 -0.003" mass="0.74"
                    diaginertia="0.003897509 0.003798579 0.001393106"/>
          <geom mesh="hip_r" material="gray" class="visual"/>

          <body name="RF_thigh_link" pos="0.0599 -0.08381 0" quat="0.707107 0 0 -0.707107">
            <inertial pos="-0.063 0.00007 0.00046" mass="2.04"
                      diaginertia="0.001805509 0.001765827 0.001053013"/>
            <geom mesh="drive" material="metal" class="visual"/>
            <geom size="0.05 0.07" pos="-0.07 0 0" quat="0.707107 0.707107 0 0" type="cylinder" class="collision"/>

            <joint name="RF_HFE" class="hfe" axis="-1 0 0"/>

            <body name="RF_thigh" pos="0 0 0" quat="0.707107 0 0 0.707107">
              <inertial pos="0.0 -0.018 -0.169" mass="1.03"
                        diaginertia="0.019312599 0.018644469 0.002838361"/>
              <geom mesh="thigh" material="gray" class="visual" quat="0 0 0 1"/>
              <geom size="0.065 0.04" pos="0 -0.04 0" quat="0.707107 0.707107 0 0" type="cylinder" class="collision"/>
              <geom size="0.0375 0.03 0.1413135" pos="0 -0.03 -0.1413135" type="box" class="collision"/>

              <body name="RF_shank_link" pos="0 -0.1003 -0.285" quat="0.707107 0 0 -0.707107">
                <inertial pos="-0.063 0.00007 0.00046" mass="2.04"
                          diaginertia="0.001805509 0.001765827 0.001053013"/>
                <geom mesh="drive" material="metal" class="visual"/>
                <geom size="0.05 0.07" pos="-0.07 0 0" quat="0.707107 0.707107 0 0" type="cylinder" class="collision"/>

                <joint name="RF_KFE" class="kfe" axis="-1 0 0"/>

                <body name="RF_shank" pos="0 0 0" quat="0.707107 0 0 0.707107">
                  <inertial pos="0.03463 -0.00688 0.00098" mass="0.33742"
                            diaginertia="0.00110974122 0.00089388521 0.00032748005"/>
                  <geom mesh="shank_r" material="gray" class="visual"/>
                  <geom size="0.06 0.02" pos="0 -0.02 0" quat="0.707107 0.707107 0 0" type="cylinder" class="collision"/>

                  <body name="RF_foot" pos="0.08795 -0.01305 -0.33797">
                    <inertial pos="0.00948 0.00948 0.1468" mass="0.25"
                              diaginertia="0.00317174097 0.00317174092 8.319196e-05"/>
                    <geom mesh="foot" material="black" class="visual" euler="0 0 0.785398163397"/>
                    <geom size="0.0175 0.141252" type="cylinder" pos="0 0 0.168985" class="collision"/>
                    <geom name="RF_foot" type="sphere" pos="0 0 0.0225" class="foot_collision"/>
                    <site name="RF_foot" class="foot" pos="0 0 0.0225"/>
                  </body>
                </body>
              </body>
            </body>
          </body>
        </body>
      </body>

      <!-- LH Leg (Left Hind) -->
      <body name="LH_hip_link" pos="-0.2999 0.104 0" quat="-0.5 0.5 0.5 -0.5">
        <inertial pos="-0.063 0.00007 0.00046" mass="2.04"
                  diaginertia="0.001805509 0.001765827 0.001053013"/>
        <geom mesh="drive" material="metal" class="visual"/>

        <joint name="LH_HAA" class="haa" axis="-1 0 0" range="-0.72 0.49"/>

        <body name="LH_hip" pos="0 0 0" quat="-0.5 -0.5 -0.5 -0.5">
          <inertial pos="-0.048 0.008 -0.003" mass="0.74"
                    diaginertia="0.003897509 0.003798579 0.001393106"/>
          <geom mesh="hip_r" material="gray" class="visual" quat="0 0 0 1"/>

          <body name="LH_thigh_link" pos="-0.0599 0.08381 0" quat="0.707107 0 0 0.707107">
            <inertial pos="-0.063 0.00007 0.00046" mass="2.04"
                      diaginertia="0.001805509 0.001765827 0.001053013"/>
            <geom mesh="drive" material="metal" class="visual"/>
            <geom size="0.05 0.07" pos="-0.07 0 0" quat="0.707107 0.707107 0 0" type="cylinder" class="collision"/>

            <joint name="LH_HFE" class="hfe"/>

            <body name="LH_thigh" pos="0 0 0" quat="0.707107 0 0 -0.707107">
              <inertial pos="-0.0 0.018 -0.169" mass="1.03"
                        diaginertia="0.019312599 0.018644469 0.002838361"/>
              <geom mesh="thigh" material="gray" class="visual"/>
              <geom size="0.065 0.04" pos="0 0.04 0" quat="0.707107 0.707107 0 0" type="cylinder" class="collision"/>
              <geom size="0.0375 0.03 0.1413135" pos="0 0.03 -0.1413135" type="box" class="collision"/>

              <body name="LH_shank_link" pos="-0.0 0.1003 -0.285" quat="0.707107 0 0 0.707107">
                <inertial pos="-0.063 0.00007 0.00046" mass="2.04"
                          diaginertia="0.001805509 0.001765827 0.001053013"/>
                <geom mesh="drive" material="metal" class="visual"/>
                <geom size="0.05 0.07" pos="-0.07 0 0" quat="0.707107 0.707107 0 0" type="cylinder" class="collision"/>

                <joint name="LH_KFE" class="kfe"/>

                <body name="LH_shank" pos="0 0 0" quat="0.707107 0 0 -0.707107">
                  <inertial pos="-0.03463 0.00688 0.00098" mass="0.33742"
                            diaginertia="0.00110974122 0.00089388521 0.00032748005"/>
                  <geom mesh="shank_r" material="gray" class="visual" quat="0 0 0 1"/>
                  <geom size="0.06 0.02" pos="0 0.02 0" quat="0.707107 0.707107 0 0" type="cylinder" class="collision"/>

                  <body name="LH_foot" pos="-0.08795 0.01305 -0.33797">
                    <inertial pos="-0.00948 -0.00948 0.1468" mass="0.25"
                              diaginertia="0.00317174097 0.00317174092 8.319196e-05"/>
                    <geom mesh="foot" material="black" class="visual" euler="0 0 -2.35619449019"/>
                    <geom size="0.0175 0.141252" type="cylinder" pos="0 0 0.168985" class="collision"/>
                    <geom name="LH_foot" type="sphere" pos="0 0 0.0225" class="foot_collision"/>
                    <site name="LH_foot" class="foot" pos="0 0 0.0225"/>
                  </body>
                </body>
              </body>
            </body>
          </body>
        </body>
      </body>

      <!-- RH Leg (Right Hind) -->
      <body name="RH_hip_link" pos="-0.2999 -0.104 0" quat="0.5 0.5 0.5 -0.5">
        <inertial pos="-0.063 0.00007 0.00046" mass="2.04"
                  diaginertia="0.001805509 0.001765827 0.001053013"/>
        <geom mesh="drive" material="metal" class="visual"/>

        <joint name="RH_HAA" class="haa" axis="-1 0 0" range="-0.49 0.72"/>

        <body name="RH_hip" pos="0 0 0" quat="0.5 -0.5 -0.5 -0.5">
          <inertial pos="-0.048 -0.008 -0.003" mass="0.74"
                    diaginertia="0.003897509 0.003798579 0.001393106"/>
          <geom mesh="hip_l" material="gray" class="visual" quat="0 0 0 1"/>

          <body name="RH_thigh_link" pos="-0.0599 -0.08381 0" quat="0.707107 0 0 -0.707107">
            <inertial pos="-0.063 0.00007 0.00046" mass="2.04"
                      diaginertia="0.001805509 0.001765827 0.001053013"/>
            <geom mesh="drive" material="metal" class="visual"/>
            <geom size="0.05 0.07" pos="-0.07 0 0" quat="0.707107 0.707107 0 0" type="cylinder" class="collision"/>

            <joint name="RH_HFE" class="hfe" axis="-1 0 0"/>

            <body name="RH_thigh" pos="0 0 0" quat="0.707107 0 0 0.707107">
              <inertial pos="-0.0 -0.018 -0.169" mass="1.03"
                        diaginertia="0.019312599 0.018644469 0.002838361"/>
              <geom mesh="thigh" material="gray" class="visual" quat="0 0 0 1"/>
              <geom size="0.065 0.04" pos="0 -0.04 0" quat="0.707107 0.707107 0 0" type="cylinder" class="collision"/>
              <geom size="0.0375 0.03 0.1413135" pos="0 -0.03 -0.1413135" type="box" class="collision"/>

              <body name="RH_shank_link" pos="-0.0 -0.1003 -0.285" quat="0.707107 0 0 -0.707107">
                <inertial pos="-0.063 0.00007 0.00046" mass="2.04"
                          diaginertia="0.001805509 0.001765827 0.001053013"/>
                <geom mesh="drive" material="metal" class="visual"/>
                <geom size="0.05 0.07" pos="-0.07 0 0" quat="0.707107 0.707107 0 0" type="cylinder" class="collision"/>

                <joint name="RH_KFE" class="kfe" axis="-1 0 0"/>

                <body name="RH_shank" pos="0 0 0" quat="0.707107 0 0 0.707107">
                  <inertial pos="-0.03463 -0.00688 0.00098" mass="0.33742"
                            diaginertia="0.00110974122 0.00089388521 0.00032748005"/>
                  <geom mesh="shank_l" material="gray" class="visual" quat="0 0 0 1"/>
                  <geom size="0.06 0.02" pos="0 -0.02 0" quat="0.707107 0.707107 0 0" type="cylinder" class="collision"/>

                  <body name="RH_foot" pos="-0.08795 -0.01305 -0.33797">
                    <inertial pos="-0.00948 0.00948 0.1468" mass="0.25"
                              diaginertia="0.00317174097 0.00317174092 8.319196e-05"/>
                    <geom mesh="foot" material="black" class="visual" euler="0 0 -3.92699081699"/>
                    <geom size="0.0175 0.141252" type="cylinder" pos="0 0 0.168985" class="collision"/>
                    <geom name="RH_foot" type="sphere" pos="0 0 0.0225" class="foot_collision"/>
                    <site name="RH_foot" class="foot" pos="0 0 0.0225"/>
                  </body>
                </body>
              </body>
            </body>
          </body>
        </body>
      </body>

    </body>
  </worldbody>

  <actuator>
    <!-- LF leg actuators -->
    <motor class="haa" name="LF_HAA" joint="LF_HAA"/>
    <motor class="hfe" name="LF_HFE" joint="LF_HFE"/>
    <motor class="kfe" name="LF_KFE" joint="LF_KFE"/>

    <!-- RF leg actuators -->
    <motor class="haa" name="RF_HAA" joint="RF_HAA"/>
    <motor class="hfe" name="RF_HFE" joint="RF_HFE"/>
    <motor class="kfe" name="RF_KFE" joint="RF_KFE"/>

    <!-- LH leg actuators -->
    <motor class="haa" name="LH_HAA" joint="LH_HAA"/>
    <motor class="hfe" name="LH_HFE" joint="LH_HFE"/>
    <motor class="kfe" name="LH_KFE" joint="LH_KFE"/>

    <!-- RH leg actuators -->
    <motor class="haa" name="RH_HAA" joint="RH_HAA"/>
    <motor class="hfe" name="RH_HFE" joint="RH_HFE"/>
    <motor class="kfe" name="RH_KFE" joint="RH_KFE"/>
  </actuator>

  <keyframe>
    <key name="home"
         qpos="0 0 0.5 1 0 0 0
               0 0.8 -1.6 0 0.8 -1.6
               0 0.8 -1.6 0 0.8 -1.6"
         ctrl="0 0.8 -1.6 0 0.8 -1.6
               0 0.8 -1.6 0 0.8 -1.6"/>
  </keyframe>
</mujoco>